<?xml version="1.0" encoding="utf-8"?>
<!-- This URDF was automatically created by SolidWorks to URDF Exporter! Originally created by Stephen Brawner (brawner@gmail.com) 
     Commit Version: 1.5.1-0-g916b5db  Build Version: 1.5.7152.31018
     For more information, please see http://wiki.ros.org/sw_urdf_exporter -->
<robot
  name="TCR050">
  <link
    name="base_link">
    <inertial>
      <origin
        xyz="5.6183E-06 0.0041848 0.022094"
        rpy="0 0 0" />
      <mass
        value="0.5937" />
      <inertia
        ixx="0.00092229"
        ixy="-1.2427E-07"
        ixz="5.0921E-09"
        iyy="0.00074441"
        iyz="1.241E-05"
        izz="0.001487" />
    </inertial>
    <visual>
      <origin
        xyz="0 0 0"
        rpy="0 0 0" />
      <geometry>
        <mesh
          filename="./meshes/base_link.STL" />
      </geometry>
      <material
        name="">
        <color
          rgba="1 1 1 1" />
      </material>
    </visual>
    <collision>
      <origin
        xyz="0 0 0"
        rpy="0 0 0" />
      <geometry>
        <mesh
          filename="./meshes/base_link.STL" />
      </geometry>
    </collision>
  </link>
  <link
    name="link1">
    <inertial>
      <origin
        xyz="-0.00934316252586657 2.98082383123899E-07 0.077245925367094"
        rpy="0 0 0" />
      <mass
        value="2.02047491224423" />
      <inertia
        ixx="0.00550362122549867"
        ixy="2.93235522041439E-08"
        ixz="-0.000248881350773848"
        iyy="0.00613876061425742"
        iyz="-5.39921512205308E-08"
        izz="0.00449475065086167" />
    </inertial>
    <visual>
      <origin
        xyz="0 0 0"
        rpy="0 0 0" />
      <geometry>
        <mesh
          filename="./meshes/link1.STL" />
      </geometry>
      <material
        name="">
        <color
          rgba="1 1 1 1" />
      </material>
    </visual>
    <collision>
      <origin
        xyz="0 0 0"
        rpy="0 0 0" />
      <geometry>
        <mesh
          filename="./meshes/link1.STL" />
      </geometry>
    </collision>
  </link>
  <joint
    name="joint1"
    type="revolute">
    <origin
      xyz="0 0 0.043"
      rpy="0 0 1.5708" />
    <parent
      link="base_link" />
    <child
      link="link1" />
    <axis
      xyz="0 0 1" />
    <limit
      lower="-3.14"
      upper="3.14"
      effort="100"
      velocity="1" />
  </joint>
  <link
    name="link2">
    <inertial>
      <origin
        xyz="0.0720133388358658 2.87034867013647E-07 -0.219749978259693"
        rpy="0 0 0" />
      <mass
        value="6.67962768871963" />
      <inertia
        ixx="0.0297875962789775"
        ixy="1.28627651652093E-07"
        ixz="5.18772136497091E-09"
        iyy="0.0330759387737247"
        iyz="2.25078226979871E-07"
        izz="0.0149651174006497" />
    </inertial>
    <visual>
      <origin
        xyz="0 0 0"
        rpy="0 0 0" />
      <geometry>
        <mesh
          filename="./meshes/link2.STL" />
      </geometry>
      <material
        name="">
        <color
          rgba="1 1 1 1" />
      </material>
    </visual>
    <collision>
      <origin
        xyz="0 0 0"
        rpy="0 0 0" />
      <geometry>
        <mesh
          filename="./meshes/link2.STL" />
      </geometry>
    </collision>
  </link>
  <joint
    name="joint2"
    type="revolute">
    <origin
      xyz="-0.075 0 0.064"
      rpy="-3.1416 0 3.1416" />
    <parent
      link="link1" />
    <child
      link="link2" />
    <axis
      xyz="1 0 0" />
    <limit
      lower="-3.14"
      upper="3.14"
      effort="100"
      velocity="1" />
  </joint>
  <link
    name="link3">
    <inertial>
      <origin
        xyz="-0.0641513660837637 0.16347325498242 8.60898297361246E-06"
        rpy="0 0 0" />
      <mass
        value="2.52519834297231" />
      <inertia
        ixx="0.0196327644832516"
        ixy="0.00232989835799296"
        ixz="3.83048800062288E-07"
        iyy="0.00324150550853782"
        iyz="2.27482514609767E-06"
        izz="0.0205540432024101" />
    </inertial>
    <visual>
      <origin
        xyz="0 0 0"
        rpy="0 0 0" />
      <geometry>
        <mesh
          filename="./meshes/link3.STL" />
      </geometry>
      <material
        name="">
        <color
          rgba="1 1 1 1" />
      </material>
    </visual>
    <collision>
      <origin
        xyz="0 0 0"
        rpy="0 0 0" />
      <geometry>
        <mesh
          filename="./meshes/link3.STL" />
      </geometry>
    </collision>
  </link>
  <joint
    name="joint3"
    type="revolute">
    <origin
      xyz="0 0 -0.4395"
      rpy="0 0 0" />
    <parent
      link="link2" />
    <child
      link="link3" />
    <axis
      xyz="1 0 0" />
    <limit
      lower="-3.14"
      upper="3.14"
      effort="100"
      velocity="1" />
  </joint>
  <link
    name="link4">
    <inertial>
      <origin
        xyz="0.036422568204088 -0.00621410103328357 8.1574342691848E-07"
        rpy="0 0 0" />
      <mass
        value="0.687607539328445" />
      <inertia
        ixx="0.000910086872861704"
        ixy="3.66666277551703E-05"
        ixz="1.7403918217511E-08"
        iyy="0.000738975681859274"
        iyz="-5.57800317384983E-09"
        izz="0.00106558830952582" />
    </inertial>
    <visual>
      <origin
        xyz="0 0 0"
        rpy="0 0 0" />
      <geometry>
        <mesh
          filename="./meshes/link4.STL" />
      </geometry>
      <material
        name="">
        <color
          rgba="1 1 1 1" />
      </material>
    </visual>
    <collision>
      <origin
        xyz="0 0 0"
        rpy="0 0 0" />
      <geometry>
        <mesh
          filename="./meshes/link4.STL" />
      </geometry>
    </collision>
  </link>
  <joint
    name="joint4"
    type="revolute">
    <origin
      xyz="-0.0095 0.353 0"
      rpy="0 0 0" />
    <parent
      link="link3" />
    <child
      link="link4" />
    <axis
      xyz="1 0 0" />
    <limit
      lower="-3.14"
      upper="3.14"
      effort="100"
      velocity="1" />
  </joint>
  <link
    name="link5">
    <inertial>
      <origin
        xyz="-1.7365846341072E-06 0.048423418980112 -0.00621410103328368"
        rpy="0 0 0" />
      <mass
        value="0.687607539328445" />
      <inertia
        ixx="0.00106562115962841"
        ixy="-1.49818800496001E-08"
        ixz="3.20395100783392E-08"
        iyy="0.000910063630958631"
        iyz="3.663634358389E-05"
        izz="0.000738985290058806" />
    </inertial>
    <visual>
      <origin
        xyz="0 0 0"
        rpy="0 0 0" />
      <geometry>
        <mesh
          filename="./meshes/link5.STL" />
      </geometry>
      <material
        name="">
        <color
          rgba="1 1 1 1" />
      </material>
    </visual>
    <collision>
      <origin
        xyz="0 0 0"
        rpy="0 0 0" />
      <geometry>
        <mesh
          filename="./meshes/link5.STL" />
      </geometry>
    </collision>
  </link>
  <joint
    name="joint5"
    type="revolute">
    <origin
      xyz="0.045 0.0505 0"
      rpy="0 0 0" />
    <parent
      link="link4" />
    <child
      link="link5" />
    <axis
      xyz="0 1 0" />
    <limit
      lower="-3.14"
      upper="3.14"
      effort="100"
      velocity="1" />
  </joint>
  <link
    name="link6">
    <inertial>
      <origin
        xyz="6.7555613961004E-05 -6.0785332471891E-06 0.00655405652337415"
        rpy="0 0 0" />
      <mass
        value="0.213014605136884" />
      <inertia
        ixx="0.000112026938738419"
        ixy="-5.29795883451615E-09"
        ixz="-1.28785309782885E-07"
        iyy="0.000115375613407327"
        iyz="5.69665499700145E-07"
        izz="0.000164441000775395" />
    </inertial>
    <visual>
      <origin
        xyz="0 0 0"
        rpy="0 0 0" />
      <geometry>
        <mesh
          filename="./meshes/link6.STL" />
      </geometry>
      <material
        name="">
        <color
          rgba="1 1 1 1" />
      </material>
    </visual>
    <collision>
      <origin
        xyz="0 0 0"
        rpy="0 0 0" />
      <geometry>
        <mesh
          filename="./meshes/link6.STL" />
      </geometry>
    </collision>
  </link>
  <joint
    name="joint6"
    type="revolute">
    <origin
      xyz="0 0.057 0.0625"
      rpy="0 0 0" />
    <parent
      link="link5" />
    <child
      link="link6" />
    <axis
      xyz="0 0 1" />
    <limit
      lower="-3.14"
      upper="3.14"
      effort="100"
      velocity="1" />
  </joint>
</robot>